<?xml version="1.0" ?>
<!-- =================================================================================== -->
<!-- |    This document was autogenerated by xacro from simple_manipulator.xacro       | -->
<!-- |    EDITING THIS FILE BY HAND IS NOT RECOMMENDED                                 | -->
<!-- =================================================================================== -->
<robot name="simple_manipulator">
  <link name="base_link">
    <inertial>
      <origin rpy="0.0 0.0 0.0" xyz="0.0 0.0 0.1"/>
      <mass value="0.1"/>
      <inertia ixx="1.0" ixy="0.0" ixz="0.0" iyy="1.0" iyz="0.0" izz="1.0"/>
    </inertial>
    <visual>
      <origin rpy="0.0 0.0 0.0" xyz="0.0 0.0 0.1"/>
      <geometry>
        <box size="0.05 0.05 0.2"/>
      </geometry>
      <material name="base_link">
        <color rgba="1.0 0.0 0.0 1.0"/>
      </material>
    </visual>
    <collision>
      <origin rpy="0.0 0.0 0.0" xyz="0.0 0.0 0.1"/>
      <geometry>
        <box size="0.05 0.05 0.2"/>
      </geometry>
    </collision>
  </link>
  <joint name="Joint1" type="revolute">
    <origin rpy="0.0 0.0 0.0" xyz="0.0 0.0 0.225"/>
    <parent link="base_link"/>
    <child link="Link1"/>
    <axis xyz="0.0 0.0 1.0"/>
    <limit effort="30.0" lower="-3.14" upper="3.14" velocity="1"/>
  </joint>
  <link name="Link1">
    <inertial>
      <origin rpy="0.0 0.0 0.0" xyz="0.0 0.0 0.1"/>
      <mass value="0.1"/>
      <inertia ixx="4.166666666666667e-05" ixy="0.0" ixz="0.0" iyy="4.166666666666667e-05" iyz="0.0" izz="0.0006666666666666668"/>
    </inertial>
    <visual>
      <origin rpy="0.0 0.0 0.0" xyz="0.0 0.0 0.1"/>
      <geometry>
        <box size="0.05 0.05 0.2"/>
      </geometry>
      <material name="link1">
        <color rgba="0.0 1.0 0.0 1.0"/>
      </material>
    </visual>
    <collision>
      <origin rpy="0.0 0.0 0.0" xyz="0.0 0.0 0.1"/>
      <geometry>
        <box size="0.05 0.05 0.2"/>
      </geometry>
    </collision>
  </link>
  <joint name="Joint2" type="revolute">
    <origin rpy="0.0 0.0 0.0" xyz="0.0 0.0 0.225"/>
    <parent link="Link1"/>
    <child link="Link2"/>
    <axis xyz="1.0 0.0 0.0"/>
    <limit effort="30" lower="-3.14" upper="3.14" velocity="1"/>
  </joint>
  <link name="Link2">
    <inertial>
      <origin rpy="0.0 0.0 0.0" xyz="0.0 0.0 0.1"/>
      <mass value="0.1"/>
      <inertia ixx="4.166666666666667e-05" ixy="0.0" ixz="0.0" iyy="4.166666666666667e-05" iyz="0.0" izz="0.0006666666666666668"/>
    </inertial>
    <visual>
      <origin rpy="0.0 0.0 0.0" xyz="0.0 0.0 0.1"/>
      <geometry>
        <box size="0.05 0.05 0.2"/>
      </geometry>
      <material name="link2">
        <color rgba="0.0 0.0 1.0 1.0"/>
      </material>
    </visual>
    <collision>
      <origin rpy="0.0 0.0 0.0" xyz="0.0 0.0 0.1"/>
      <geometry>
        <box size="0.05 0.05 0.2"/>
      </geometry>
    </collision>
  </link>
  <joint name="Joint3" type="revolute">
    <origin rpy="0.0 0.0 0.0" xyz="0.0 0.0 0.225"/>
    <parent link="Link2"/>
    <child link="Link3"/>
    <axis xyz="1.0 0.0 0.0"/>
    <limit effort="30" lower="-3.14" upper="3.14" velocity="1"/>
  </joint>
  <link name="Link3">
    <inertial>
      <origin rpy="0.0 0.0 0.0" xyz="0.0 0.0 0.1"/>
      <mass value="0.1"/>
      <inertia ixx="4.166666666666667e-05" ixy="0.0" ixz="0.0" iyy="4.166666666666667e-05" iyz="0.0" izz="0.0006666666666666668"/>
    </inertial>
    <visual>
      <origin rpy="0.0 0.0 0.0" xyz="0.0 0.0 0.1"/>
      <geometry>
        <box size="0.05 0.05 0.2"/>
      </geometry>
      <material name="link3">
        <color rgba="0.0 1.0 1.0 1.0"/>
      </material>
    </visual>
    <collision>
      <origin rpy="0.0 0.0 0.0" xyz="0.0 0.0 0.1"/>
      <geometry>
        <box size="0.05 0.05 0.2"/>
      </geometry>
    </collision>
  </link>
</robot>
